Unhandled exception in thread started by <function wrapper at 0x36c7410>
Traceback (most recent call last):
  File "/usr/lib/python2.7/site-packages/django/utils/autoreload.py", line 226, in wrapper
    fn(*args, **kwargs)
  File "/usr/lib/python2.7/site-packages/django/core/management/commands/runserver.py", line 109, in inner_run
    autoreload.raise_last_exception()
  File "/usr/lib/python2.7/site-packages/django/utils/autoreload.py", line 249, in raise_last_exception
    six.reraise(*_exception)
  File "/usr/lib/python2.7/site-packages/django/utils/autoreload.py", line 226, in wrapper
    fn(*args, **kwargs)
  File "/usr/lib/python2.7/site-packages/django/__init__.py", line 18, in setup
    apps.populate(settings.INSTALLED_APPS)
  File "/usr/lib/python2.7/site-packages/django/apps/registry.py", line 108, in populate
    app_config.import_models(all_models)
  File "/usr/lib/python2.7/site-packages/django/apps/config.py", line 202, in import_models
    self.models_module = import_module(models_module_name)
  File "/usr/lib64/python2.7/importlib/__init__.py", line 37, in import_module
    __import__(name)
  File "/home/lua1/Tracker/data_tracker/tracker/models.py", line 95
    = models.CharField(max_length=11, choices=TRACKERID_CHOICES, default='0')
                                                                            ^
IndentationError: unindent does not match any outer indentation level
CommandError: "0.3838" is not a valid port number or address:port pair.
Unhandled exception in thread started by <function wrapper at 0x30f7410>
Traceback (most recent call last):
  File "/usr/lib/python2.7/site-packages/django/utils/autoreload.py", line 226, in wrapper
    fn(*args, **kwargs)
  File "/usr/lib/python2.7/site-packages/django/core/management/commands/runserver.py", line 109, in inner_run
    autoreload.raise_last_exception()
  File "/usr/lib/python2.7/site-packages/django/utils/autoreload.py", line 249, in raise_last_exception
    six.reraise(*_exception)
  File "/usr/lib/python2.7/site-packages/django/utils/autoreload.py", line 226, in wrapper
    fn(*args, **kwargs)
  File "/usr/lib/python2.7/site-packages/django/__init__.py", line 18, in setup
    apps.populate(settings.INSTALLED_APPS)
  File "/usr/lib/python2.7/site-packages/django/apps/registry.py", line 108, in populate
    app_config.import_models(all_models)
  File "/usr/lib/python2.7/site-packages/django/apps/config.py", line 202, in import_models
    self.models_module = import_module(models_module_name)
  File "/usr/lib64/python2.7/importlib/__init__.py", line 37, in import_module
    __import__(name)
  File "/home/lua1/Tracker/data_tracker/tracker/models.py", line 95
    = models.CharField(max_length=11, choices=TRACKERID_CHOICES, default='0')
                                                                            ^
IndentationError: unindent does not match any outer indentation level
Unhandled exception in thread started by <function wrapper at 0x28d6410>
Traceback (most recent call last):
  File "/usr/lib/python2.7/site-packages/django/utils/autoreload.py", line 226, in wrapper
    fn(*args, **kwargs)
  File "/usr/lib/python2.7/site-packages/django/core/management/commands/runserver.py", line 109, in inner_run
    autoreload.raise_last_exception()
  File "/usr/lib/python2.7/site-packages/django/utils/autoreload.py", line 249, in raise_last_exception
    six.reraise(*_exception)
  File "/usr/lib/python2.7/site-packages/django/utils/autoreload.py", line 226, in wrapper
    fn(*args, **kwargs)
  File "/usr/lib/python2.7/site-packages/django/__init__.py", line 18, in setup
    apps.populate(settings.INSTALLED_APPS)
  File "/usr/lib/python2.7/site-packages/django/apps/registry.py", line 108, in populate
    app_config.import_models(all_models)
  File "/usr/lib/python2.7/site-packages/django/apps/config.py", line 202, in import_models
    self.models_module = import_module(models_module_name)
  File "/usr/lib64/python2.7/importlib/__init__.py", line 37, in import_module
    __import__(name)
  File "/home/lua1/Tracker/data_tracker/tracker/models.py", line 95
    = models.CharField(max_length=11, choices=TRACKERID_CHOICES, default='0')
                                                                            ^
IndentationError: unindent does not match any outer indentation level
/usr/lib/python2.7/site-packages/django_filters/filterset.py:103: RemovedInDjango110Warning: 'get_field_by_name is an unofficial API that has been deprecated. You may be able to replace it with 'get_field()'
  rel, model, direct, m2m = opts.get_field_by_name(parts[-1])

/usr/lib/python2.7/site-packages/django_filters/filterset.py:103: RemovedInDjango110Warning: 'get_field_by_name is an unofficial API that has been deprecated. You may be able to replace it with 'get_field()'
  rel, model, direct, m2m = opts.get_field_by_name(parts[-1])

Error: That port is already in use.
